Workbook

Sheet AS03-MP01
A1: RBPR-2425-030-AS03-MP01.SLDDRW
A2: Raw Material cost (Mild steel)
A3: Sno | B3: Descriptions | C3: Usage | D3: Volume | E3: Weight in kg | F3: Rate per kg | G3: Final Cost
A4: 1 | B4: Raw Material | C4: 800*750*40 | D4: - | E4: 188 | F4: 75 | G4: =E4*F4 -> 14100
A6: Machining Cost
A7: Sno | B7: Descriptions | C7: Total setups | D7: setup cost | E7: Machining hours | F7: Machining Rate/hr | G7: Final Cost
A8: 1 | B8: Cnc Machining 3axis | C8: 2 | D8: 1500 | E8: 48 | F8: 400 | G8: =F8*E8+D8 -> 20700
A9: 2 | B9: Grinding | C9: 2 | D9: 1500 | E9: 12 | F9: 500 | G9: =F9*E9+D9 -> 7500
A11: Post Processing Cost
A12: Sno | B12: Descriptions | C12: - | F12: Rate | G12: Final Cost
A13: 1 | B13: Tapping M20*2.5mm | C13: - | F13: 5000 | G13: =F13 -> 5000
A14: 2 | B14: Electroless Nickel Plating | C14: - | F14: 5000 | G14: =F14 -> 5000
A15: 3 | B15: Sandblasting | C15: - | F15: 3000 | G15: =F15 -> 3000
A17: Inspection
A18: Sno | B18: Descriptions | C18: Total Setups | D18: Setup Cost | E18: Inspection Hours | F18: Rate/hr | G18: Final Cost
A19: 1 | B19: CMM Inspection | C19: 1 | D19: 1000 | E19: 2 | F19: 1000 | G19: =F19*E19+D19 -> 3000
A20: 2 | B20: Manual Inspection | C20: - | D20: - | E20: - | F20: 500 | G20: 500
A22: Logistics and packaging
A23: Sno. | B23: Descriptions | C23: Comments | F23: Rate | G23: Final cost
A24: 1 | B24: Packaging | C24: Wooden box with foams and bubble wrap | F24: 3000 | G24: 3000
A25: 2 | B25: Logistics | C25: By train | F25: 3000 | G25: 3000
A27: Any Other Cost
A28: Sno. | B28: Descriptions | C28: Comments | F28: Rate | G28: Final cost
A29: 1 | F29: 0 | G29: 0
A31: Grand Total | G31: =G4+G8+G9+G13+G14+G15+G19+G20+G24+G25+G29 -> 64800

Sheet AS01
A1: RBPR-2425-030-AS01-MP01.SLDDRW
A2: Raw Material cost (Mild steel)
A3: Sno | B3: Descriptions | C3: Usage | D3: Volume | E3: Weight in kg | F3: Rate per kg | G3: Final Cost
A4: 1 | B4: Raw Material | C4: Dia150*50mm | D4: - | E4: 4 | F4: 75 | G4: =E4*F4 -> 300
A6: Machining Cost
A7: Sno | B7: Descriptions | C7: Total setups | D7: setup cost | E7: Machining hours | F7: Machining Rate/hr | G7: Final Cost
A8: 1 | B8: Cnc Machining 3axis | C8: 2 | D8: 1500 | E8: 10 | F8: 400 | G8: =F8*E8+D8 -> 5500
A9: 2 | B9: Cnc Turning | C9: 2 | D9: 1500 | E9: 4 | F9: 400 | G9: =F9*E9+D9 -> 3100
A10: 3 | B10: Grinding | C10: 1 | D10: 750 | E10: 3 | F10: 500 | G10: =F10*E10+D10 -> 2250
A12: Post Processing Cost
A13: Sno | B13: Descriptions | C13: - | F13: Rate | G13: Final Cost
A14: 1 | B14: Tapping M6 | C14: - | F14: 2000 | G14: =F14 -> 2000
A15: 2 | B15: Electroless Nickel Plating | C15: - | F15: 1000 | G15: =F15 -> 1000
A16: 3 | B16: Sandblasting | C16: - | F16: 1000 | G16: =F16 -> 1000
A18: Inspection
A19: Sno | B19: Descriptions | C19: Total Setups | D19: Setup Cost | E19: Inspection Hours | F19: Rate/hr | G19: Final Cost
A20: 1 | B20: CMM Inspection | C20: 1 | D20: 1000 | E20: 2 | F20: 1000 | G20: =F20*E20+D20 -> 3000
A21: 2 | B21: Manual Inspection | C21: - | D21: - | E21: - | F21: 500 | G21: 500
A23: Logistics and packaging
A24: Sno. | B24: Descriptions | C24: Comments | F24: Rate | G24: Final cost
A25: 1 | B25: Packaging | C25: Wooden box with foams and bubble wrap | F25: 500 | G25: 500
A26: 2 | B26: Logistics | C26: - | F26: 500 | G26: 500
A28: Any Other Cost
A29: Sno. | B29: Descriptions | C29: Comments | F29: Rate | G29: Final cost
A30: 1 | B30: Reamer dia 8 | F30: 1500 | G30: 1500
A32: Grand Total | G32: =G4+G8+G9+G14+G15+G16+G20+G21+G25+G26+G30+G10 -> 21150
A36: RBPR-2425-030-AS01-MP04.SLDDRW
A37: Raw Material cost (Mild steel)
A38: Sno | B38: Descriptions | C38: Usage | D38: Volume | E38: Weight in kg | F38: Rate per kg | G38: Final Cost
A39: 1 | B39: Raw Material | C39: 110*110*35mm | D39: - | E39: 8 | F39: 75 | G39: =E39*F39 -> 600
A41: Machining Cost
A42: Sno | B42: Descriptions | C42: Total setups | D42: setup cost | E42: Machining hours | F42: Machining Rate/hr | G42: Final Cost
A43: 1 | B43: Cnc Machining 3axis | C43: 2 | D43: 1500 | E43: 10 | F43: 400 | G43: =F43*E43+D43 -> 5500
A44: 2 | B44: Grinding | C44: 2 | D44: 750 | E44: 3 | F44: 500 | G44: =F44*E44+D44 -> 2250
A46: Post Processing Cost
A47: Sno | B47: Descriptions | C47: - | F47: Rate | G47: Final Cost
A48: 1 | B48: Tapping M8 | C48: - | F48: 2000 | G48: =F48 -> 2000
A49: 2 | B49: Electroless Nickel Plating | C49: - | F49: 1000 | G49: =F49 -> 1000
A50: 3 | B50: Sandblasting | C50: - | F50: 1000 | G50: =F50 -> 1000
A52: Inspection
...

Sheet AS05
A1: RBPR-2425-030-AS05-MP01.SLDDRW
A2: Raw Material cost (Mild steel)
A3: Sno | B3: Descriptions | C3: Usage | D3: Volume | E3: Weight in kg | F3: Rate per kg | G3: Final Cost
A4: 1 | B4: Raw Material | C4: Dia150*50mm | D4: - | E4: 3 | F4: 75 | G4: =E4*F4 -> 225
A6: Machining Cost
A7: Sno | B7: Descriptions | C7: Total setups | D7: setup cost | E7: Machining hours | F7: Machining Rate/hr | G7: Final Cost
A8: 1 | B8: Cnc Machining 3axis | C8: 2 | D8: 1500 | E8: 5 | F8: 400 | G8: =F8*E8+D8 -> 3500
A9: 2 | B9: Cnc Turning | C9: 1 | D9: 750 | E9: 2 | F9: 400 | G9: =F9*E9+D9 -> 1550
A11: Post Processing Cost
A12: Sno | B12: Descriptions | C12: - | F12: Rate | G12: Final Cost
A13: 1 | B13: Tapping M5 | C13: - | F13: 1500 | G13: =F13 -> 1500
A14: 2 | B14: Electroless Nickel Plating | C14: - | F14: 1000 | G14: =F14 -> 1000
A15: 3 | B15: Sandblasting | C15: - | F15: 1000 | G15: =F15 -> 1000
A17: Inspection
A18: Sno | B18: Descriptions | C18: Total Setups | D18: Setup Cost | E18: Inspection Hours | F18: Rate/hr | G18: Final Cost
A19: 1 | B19: Manual Inspection | C19: - | D19: - | E19: - | F19: 500 | G19: 500
A21: Logistics and packaging
A22: Sno. | B22: Descriptions | C22: Comments | F22: Rate | G22: Final cost
A23: 1 | B23: Packaging | C23: Wooden box with foams and bubble wrap | F23: 500 | G23: 500
A24: 2 | B24: Logistics | C24: - | F24: 500 | G24: 500
A26: Any Other Cost
A27: Sno. | B27: Descriptions | C27: Comments | F27: Rate | G27: Final cost
A28: 1 | B28: Reamer dia 5 | F28: 1500 | G28: 1500
A30: Grand Total | G30: =G4+G8+G9+G13+G14+G15+G19+G23+G24+G28 -> 11775
A34: RBPR-2425-030-AS05-MP02.SLDDRW
A35: Raw Material cost (Mild steel)
A36: Sno | B36: Descriptions | C36: Usage | D36: Volume | E36: Weight in kg | F36: Rate per kg | G36: Final Cost
A37: 1 | B37: Raw Material | C37: 200*100*20 | D37: - | E37: 4 | F37: 75 | G37: =E37*F37 -> 300
A39: Machining Cost
A40: Sno | B40: Descriptions | C40: Total setups | D40: setup cost | E40: Machining hours | F40: Machining Rate/hr | G40: Final Cost
A41: 1 | B41: Cnc Machining 3axis | C41: 3 | D41: 2150 | E41: 10 | F41: 400 | G41: =F41*E41+D41 -> 6150
A44: Post Processing Cost
A45: Sno | B45: Descriptions | C45: - | F45: Rate | G45: Final Cost
A46: 1 | B46: Tapping M5 | C46: Considered in previous quote | F46: 0 | G46: =F46 -> 0
A47: 2 | B47: White Anodizing | C47: - | F47: 1000 | G47: =F47 -> 1000
A48: 3
A50: Inspection
A51: Sno | B51: Descriptions | C51: Total Setups | D51: Setup Cost | E51: Inspection Hours | F51: Rate/hr | G51: Final Cost
A52: 1 | B52: Manual Inspection | C52: - | D52: - | E52: - | F52: 500 | G52: 500
A54: Logistics and packaging
...

Sheet Final Quote
A1: Sno. | B1: Part Name | C1: Qty | D1: Material | E1: Surface Finish | F1: Cost
A2: 1 | B2: RBPR-2425-030-AS03-MP01.SLDDRW | C2: 1 | D2: Mild steel | E2: Electroless Nickel Plating Sand Blasting | F2: ='AS03-MP01'!G31 -> 64800
A3: 2 | B3: RBPR-2425-030-AS01-MP01.SLDDRW | C3: 1 | D3: Mild steel | E3: Electroless Nickel Plating Sand Blasting | F3: ='AS01'!G32 -> 21150
A4: 3 | B4: RBPR-2425-030-AS01-MP04.SLDDRW | C4: 1 | D4: Mild steel | E4: Electroless Nickel Plating Sand Blasting | F4: ='AS01'!G66 -> 16850
A5: 4 | B5: RBPR-2425-030-AS01-MP06.SLDDRW | C5: 1 | D5: Mild steel | E5: Electroless Nickel Plating Sand Blasting | F5: ='AS01'!G100 -> 13225
A6: 5 | B6: RBPR-2425-030-AS01-MP05.SLDDRW | C6: 1 | D6: Mild steel | E6: Electroless Nickel Plating Sand Blasting | F6: ='AS01'!G137 -> 28225
A7: 6 | B7: RBPR-2425-030-AS05-MP01.SLDDRW | C7: 1 | D7: Mild steel | E7: Electroless Nickel Plating Sand Blasting | F7: ='AS05'!G30 -> 11775
A8: 7 | B8: RBPR-2425-030-AS05-MP02.SLDDRW | C8: 1 | D8: Mild steel | E8: White Anodizing | F8: ='AS05'!G63 -> 8950
A9: 8 | B9: RBPR-2425-030-AS05-MP03.SLDDRW | C9: 1 | D9: Mild steel | E9: White Anodizing | F9: ='AS05'!G96 -> 9025
A10: 9 | B10: RBPR-2425-030-AS05-MP04.SLDDRW | C10: 1 | D10: Mild steel | E10: Electroless Nickel Plating Sand Blasting | F10: ='AS05'!G130 -> 17100
A11: 10 | B11: RBPR-2425-030-AS05-MP07.SLDDRW | C11: 2 | D11: Mild steel | E11: Electroless Nickel Plating Sand Blasting | F11: ='AS05'!G164 -> 13650
A12: 11 | B12: RBPR-2425-030-AS05-MP08.SLDDRW | C12: 1 | D12: Mild steel | E12: Powdercoating RAL 9005 (Jet black) | F12: ='AS05'!G198 -> 10150
A14: Grand Total | F14: =SUM(F2:F12) -> 214900
